<?xml version="1.0" encoding="utf-8"?>
<!-- This URDF was automatically created by SolidWorks to URDF Exporter! Originally created by Stephen Brawner (brawner@gmail.com) 
     Commit Version: 1.6.0-4-g7f85cfe  Build Version: 1.6.7995.38578
     For more information, please see http://wiki.ros.org/sw_urdf_exporter -->
<robot
  name="starship">
  <link
    name="body">
    <inertial>
      <origin
        xyz="-0.054083 -7.3943E-06 -0.00013286"
        rpy="0 0 0" />
      <mass
        value="75806" />
      <inertia
        ixx="1293500"
        ixy="5.3291E-09"
        ixz="3212.3"
        iyy="14695000"
        iyz="5.3016E-12"
        izz="14695000" />
    </inertial>
    <visual>
      <origin
        xyz="0 0 0"
        rpy="0 0 0" />
      <geometry>
        <mesh
          filename="../meshes/body.obj" />
      </geometry>
      <material
        name="">
        <color
          rgba="0.77647 0.75686 0.73725 1" />
      </material>
    </visual>
    <collision>
      <origin
        xyz="0 0 0"
        rpy="0 0 0" />
      <geometry>
        <mesh
          filename="../meshes/body.obj" />
      </geometry>
    </collision>
  </link>
  <link
    name="Link_Leg_R">
    <inertial>
      <origin
        xyz="-2.2787E-05 -1.8808 0.0011883"
        rpy="0 0 0" />
      <mass
        value="3334.5" />
      <inertia
        ixx="5374.2"
        ixy="-4459.8"
        ixz="-1.9212E-11"
        iyy="45100"
        iyz="-8.6282E-13"
        izz="50379" />
    </inertial>
    <visual>
      <origin
        xyz="0 0 0"
        rpy="0 0 0" />
      <geometry>
        <mesh
          filename="../meshes/Link_Leg_R.obj" />
      </geometry>
      <material
        name="">
        <color
          rgba="0.77647 0.75686 0.73725 1" />
      </material>
    </visual>
    <collision>
      <origin
        xyz="0 0 0"
        rpy="0 0 0" />
      <geometry>
        <mesh
          filename="../meshes/Link_Leg_R.obj" />
      </geometry>
    </collision>
  </link>
  <joint
    name="Joint_Leg_R"
    type="revolute">
    <origin
      xyz="-15.755 -4.9107 -0.0011883"
      rpy="0 0 0" />
    <parent
      link="body" />
    <child
      link="Link_Leg_R" />
    <axis
      xyz="-1 0 0" />
    <limit
      lower="-1.57"
      upper="1.57"/>
  </joint>
  <link
    name="Link_Leg_L">
    <inertial>
      <origin
        xyz="-2.2787E-05 1.8808 0.0011883"
        rpy="0 0 0" />
      <mass
        value="3334.5" />
      <inertia
        ixx="5374.2"
        ixy="4459.8"
        ixz="-8.7792E-13"
        iyy="45100"
        iyz="-1.0595E-12"
        izz="50379" />
    </inertial>
    <visual>
      <origin
        xyz="0 0 0"
        rpy="0 0 0" />
      <geometry>
        <mesh
          filename="../meshes/Link_Leg_L.obj" />
      </geometry>
      <material
        name="">
        <color
          rgba="0.77647 0.75686 0.73725 1" />
      </material>
    </visual>
    <collision>
      <origin
        xyz="0 0 0"
        rpy="0 0 0" />
      <geometry>
        <mesh
          filename="../meshes/Link_Leg_L.obj" />
      </geometry>
    </collision>
  </link>
  <joint
    name="Joint_Leg_L"
    type="revolute">
    <origin
      xyz="-15.755 4.9107 -0.0011883"
      rpy="0 0 0" />
    <parent
      link="body" />
    <child
      link="Link_Leg_L" />
    <axis
      xyz="-1 0 0" />
    <limit
      lower="-1.57"
      upper="1.57"/>
  </joint>
  <link
    name="Link_Arm_R">
    <inertial>
      <origin
        xyz="-9.3823E-06 -1.2616 1.2507E-08"
        rpy="0 0 0" />
      <mass
        value="1190.6" />
      <inertia
        ixx="919.98"
        ixy="-634.06"
        ixz="-0.59721"
        iyy="4386.3"
        iyz="-0.83543"
        izz="5273.3" />
    </inertial>
    <visual>
      <origin
        xyz="0 0 0"
        rpy="0 0 0" />
      <geometry>
        <mesh
          filename="../meshes/Link_Arm_R.obj" />
      </geometry>
      <material
        name="">
        <color
          rgba="0.77647 0.75686 0.73725 1" />
      </material>
    </visual>
    <collision>
      <origin
        xyz="0 0 0"
        rpy="0 0 0" />
      <geometry>
        <mesh
          filename="../meshes/Link_Arm_R.obj" />
      </geometry>
    </collision>
  </link>
  <joint
    name="Joint_Arm_R"
    type="revolute">
    <origin
      xyz="17.299 -4.6556 -0.0011883"
      rpy="-0.00094188 0 0.1782" />
    <parent
      link="body" />
    <child
      link="Link_Arm_R" />
    <axis
      xyz="-1 0 0" />
    <limit
      lower="-1.57"
      upper="1.57"/>
  </joint>
  <link
    name="Link_Arm_L">
    <inertial>
      <origin
        xyz="-6.7609E-06 1.2616 2.6215E-08"
        rpy="0 0 0" />
      <mass
        value="1190.6" />
      <inertia
        ixx="919.98"
        ixy="634.06"
        ixz="-0.5972"
        iyy="4386.3"
        iyz="0.83542"
        izz="5273.3" />
    </inertial>
    <visual>
      <origin
        xyz="0 0 0"
        rpy="0 0 0" />
      <geometry>
        <mesh
          filename="../meshes/Link_Arm_L.obj" />
      </geometry>
      <material
        name="">
        <color
          rgba="0.77647 0.75686 0.73725 1" />
      </material>
    </visual>
    <collision>
      <origin
        xyz="0 0 0"
        rpy="0 0 0" />
      <geometry>
        <mesh
          filename="../meshes/Link_Arm_L.obj" />
      </geometry>
    </collision>
  </link>
  <joint
    name="Joint_Arm_L"
    type="revolute">
    <origin
      xyz="17.299 4.6556 -0.0011883"
      rpy="0.00094187 0 -0.1782" />
    <parent
      link="body" />
    <child
      link="Link_Arm_L" />
    <axis
      xyz="-1 0 0" />
    <limit
      lower="-1.57"
      upper="1.57"/>
  </joint>

  <drake:collision_filter_group name="group1">
    <drake:member link="Link_Leg_L"/>
    <drake:ignored_collision_filter_group name="group2"/>
    <drake:ignored_collision_filter_group name="group3"/>
    <drake:ignored_collision_filter_group name="group4"/>
  </drake:collision_filter_group>

  <drake:collision_filter_group name="group2">
    <drake:member link="Link_Leg_R"/>
    <drake:ignored_collision_filter_group name="group1"/>
    <drake:ignored_collision_filter_group name="group3"/>
    <drake:ignored_collision_filter_group name="group4"/>
  </drake:collision_filter_group>

  <drake:collision_filter_group name="group3">
    <drake:member link="Link_Arm_L"/>
    <drake:ignored_collision_filter_group name="group2"/>
    <drake:ignored_collision_filter_group name="group1"/>
    <drake:ignored_collision_filter_group name="group4"/>
  </drake:collision_filter_group>

  <drake:collision_filter_group name="group4">
    <drake:member link="Link_Arm_R"/>
    <drake:ignored_collision_filter_group name="group2"/>
    <drake:ignored_collision_filter_group name="group3"/>
    <drake:ignored_collision_filter_group name="group1"/>
  </drake:collision_filter_group>
</robot>