<?xml version="1.0" encoding="utf-8"?>
<!-- This URDF was automatically created by SolidWorks to URDF Exporter! Originally created by Stephen Brawner (brawner@gmail.com) 
     Commit Version: 1.6.0-4-g7f85cfe  Build Version: 1.6.7995.38578
     For more information, please see http://wiki.ros.org/sw_urdf_exporter -->
<robot
  name="starship-mini">
  <link
    name="body">
    <inertial>
      <origin
        xyz="0.00040217 -1.0547E-15 0.0011895"
        rpy="0 0 0" />
      <mass
        value="119.07" />
      <inertia
        ixx="3.1118"
        ixy="-7.9288E-13"
        ixz="2.245E-05"
        iyy="36.378"
        iyz="-2.1445E-15"
        izz="36.379" />
    </inertial>
    <visual>
      <origin
        xyz="0 0 0"
        rpy="0 0 0" />
      <geometry>
        <mesh
          filename="../meshes/body.obj" />
      </geometry>
      <material
        name="">
        <color
          rgba="0.77647 0.75686 0.73725 1" />
      </material>
    </visual>
    <collision>
      <origin
        xyz="0 0 0"
        rpy="0 0 0" />
      <geometry>
        <mesh
          filename="../meshes/body.obj" />
      </geometry>
    </collision>
  </link>
  <link
    name="Link_Leg_R">
    <inertial>
      <origin
        xyz="0.00042808 -0.075147 0.0011883"
        rpy="0 0 0" />
      <mass
        value="5.4307" />
      <inertia
        ixx="0.014344"
        ixy="-0.011727"
        ixz="-3.1322E-14"
        iyy="0.11851"
        iyz="-3.6568E-14"
        izz="0.1322" />
    </inertial>
    <visual>
      <origin
        xyz="0 0 0"
        rpy="0 0 0" />
      <geometry>
        <mesh
          filename="../meshes/Link_Leg_R.obj" />
      </geometry>
      <material
        name="">
        <color
          rgba="0.77647 0.75686 0.73725 1" />
      </material>
    </visual>
    <collision>
      <origin
        xyz="0 0 0"
        rpy="0 0 0" />
      <geometry>
        <mesh
          filename="../meshes/Link_Leg_R.obj" />
      </geometry>
    </collision>
  </link>
  <joint
    name="Joint_Leg_R"
    type="revolute">
    <origin
      xyz="-0.6302 -0.19643 0"
      rpy="0 0 0" />
    <parent
      link="body" />
    <child
      link="Link_Leg_R" />
    <axis
      xyz="-1 0 0" />
    <limit
      lower="-1.57"
      upper="1.57"/>
  </joint>
  <link
    name="Link_Leg_L">
    <inertial>
      <origin
        xyz="0.00042808 0.075147 0.0011883"
        rpy="0 0 0" />
      <mass
        value="5.4307" />
      <inertia
        ixx="0.014344"
        ixy="0.011727"
        ixz="-2.9461E-16"
        iyy="0.11851"
        iyz="8.2908E-20"
        izz="0.1322" />
    </inertial>
    <visual>
      <origin
        xyz="0 0 0"
        rpy="0 0 0" />
      <geometry>
        <mesh
          filename="../meshes/Link_Leg_L.obj" />
      </geometry>
      <material
        name="">
        <color
          rgba="0.77647 0.75686 0.73725 1" />
      </material>
    </visual>
    <collision>
      <origin
        xyz="0 0 0"
        rpy="0 0 0" />
      <geometry>
        <mesh
          filename="../meshes/Link_Leg_L.obj" />
      </geometry>
    </collision>
  </link>
  <joint
    name="Joint_Leg_L"
    type="revolute">
    <origin
      xyz="-0.6302 0.19643 0"
      rpy="0 0 0" />
    <parent
      link="body" />
    <child
      link="Link_Leg_L" />
    <axis
      xyz="-1 0 0" />
    <limit
      lower="-1.57"
      upper="1.57"/>
  </joint>
  <link
    name="Link_Arm_R">
    <inertial>
      <origin
        xyz="0.00014768 -0.050416 0.0011883"
        rpy="0 0 0" />
      <mass
        value="1.9535" />
      <inertia
        ixx="0.0024956"
        ixy="-0.0016703"
        ixz="3.6378E-17"
        iyy="0.011631"
        iyz="-6.6753E-18"
        izz="0.013902" />
    </inertial>
    <visual>
      <origin
        xyz="0 0 0"
        rpy="0 0 0" />
      <geometry>
        <mesh
          filename="../meshes/Link_Arm_R.obj" />
      </geometry>
      <material
        name="">
        <color
          rgba="0.77647 0.75686 0.73725 1" />
      </material>
    </visual>
    <collision>
      <origin
        xyz="0 0 0"
        rpy="0 0 0" />
      <geometry>
        <mesh
          filename="../meshes/Link_Arm_R.obj" />
      </geometry>
    </collision>
  </link>
  <joint
    name="Joint_Arm_R"
    type="revolute">
    <origin
      xyz="0.69204 -0.18622 0"
      rpy="0 0 0.1782" />
    <parent
      link="body" />
    <child
      link="Link_Arm_R" />
    <axis
      xyz="-1 0 0" />
    <limit
      lower="-1.57"
      upper="1.57"/>
  </joint>
  <link
    name="Link_Arm_L">
    <inertial>
      <origin
        xyz="0.00014768 0.050416 0.0011883"
        rpy="0 0 0" />
      <mass
        value="1.9535" />
      <inertia
        ixx="0.0024956"
        ixy="0.0016703"
        ixz="-1.7101E-14"
        iyy="0.011631"
        iyz="2.3179E-14"
        izz="0.013902" />
    </inertial>
    <visual>
      <origin
        xyz="0 0 0"
        rpy="0 0 0" />
      <geometry>
        <mesh
          filename="../meshes/Link_Arm_L.obj" />
      </geometry>
      <material
        name="">
        <color
          rgba="0.77647 0.75686 0.73725 1" />
      </material>
    </visual>
    <collision>
      <origin
        xyz="0 0 0"
        rpy="0 0 0" />
      <geometry>
        <mesh
          filename="../meshes/Link_Arm_L.obj" />
      </geometry>
    </collision>
  </link>
  <joint
    name="Joint_Arm_L"
    type="revolute">
    <origin
      xyz="0.69204 0.18622 0"
      rpy="0 0 -0.1782" />
    <parent
      link="body" />
    <child
      link="Link_Arm_L" />
    <axis
      xyz="-1 0 0" />
    <limit
      lower="-1.57"
      upper="1.57"/>
  </joint>

  <drake:collision_filter_group name="group1">
    <drake:member link="Link_Leg_L"/>
    <drake:ignored_collision_filter_group name="group2"/>
    <drake:ignored_collision_filter_group name="group3"/>
    <drake:ignored_collision_filter_group name="group4"/>
  </drake:collision_filter_group>

  <drake:collision_filter_group name="group2">
    <drake:member link="Link_Leg_R"/>
    <drake:ignored_collision_filter_group name="group1"/>
    <drake:ignored_collision_filter_group name="group3"/>
    <drake:ignored_collision_filter_group name="group4"/>
  </drake:collision_filter_group>

  <drake:collision_filter_group name="group3">
    <drake:member link="Link_Arm_L"/>
    <drake:ignored_collision_filter_group name="group2"/>
    <drake:ignored_collision_filter_group name="group1"/>
    <drake:ignored_collision_filter_group name="group4"/>
  </drake:collision_filter_group>

  <drake:collision_filter_group name="group4">
    <drake:member link="Link_Arm_R"/>
    <drake:ignored_collision_filter_group name="group2"/>
    <drake:ignored_collision_filter_group name="group3"/>
    <drake:ignored_collision_filter_group name="group1"/>
  </drake:collision_filter_group>
</robot>